Workbook

Sheet DASHBOARD
B2: ◆ CUSTOMER CHURN ANALYSIS & RETENTION ROI DASHBOARD ◆
B5: SaaS Subscription Analytics | Formula-Driven | Auto-Recalculating
B7: TOTAL CUSTOMERS | G7: TOTAL CHURNED | L7: OVERALL CHURN RATE | Q7: TOTAL MRR LOST
B8: =COUNTA(Calculations!A2:A1001) -> 1000 | G8: =SUM(Calculations!G2:G1001) -> 168 | L8: =IFERROR(SUM(Calculations!G2:G1001)/COUNTA(Calculations!A2:A1001),0) -> 0.168 | Q8: =SUM(Calculations!P2:P1001) -> 42000
B12: AT-RISK CUSTOMERS | G12: RETENTION ROI (10% LIFT) | L12: AVG TENURE (MONTHS) | Q12: AVG LIFETIME VALUE
B13: =SUM(Calculations!O2:O1001) -> 109 | G13: =WhatIf_Scenarios!B18 -> 0.20004001 | L13: =ROUND(AVERAGE(Calculations!L2:L1001),1) -> 15.4 | Q13: =ROUND(AVERAGE(Calculations!M2:M1001),0) -> 3827
B17: ▐────────────────────────────────────────────────────────────────────────────────▌
B18: ■ PLAN SEGMENT BREAKDOWN
B19: Plan | C19: Customers | D19: Churned | E19: Churn % | F19: MRR Lost | G19: Avg LTV
B20: Basic | C20: =COUNTIF(Calculations!C2:C1001,B20) -> 327 | D20: =COUNTIFS(Calculations!C2:C1001,B20,Calculations!G2:G1001,1) -> 58 | E20: =IFERROR(D20/C20,0) -> 0.17737003 | F20: =SUMIFS(Calculations!P2:P1001,Calculations!C2:C1001,B20) -> 2900 | G20: =IFERROR(AVERAGEIF(Calculations!C2:C1001,B20,Calculations!M2:M1001),0) -> 772.32416
B21: Pro | C21: =COUNTIF(Calculations!C2:C1001,B21) -> 343 | D21: =COUNTIFS(Calculations!C2:C1001,B21,Calculations!G2:G1001,1) -> 53 | E21: =IFERROR(D21/C21,0) -> 0.15451895 | F21: =SUMIFS(Calculations!P2:P1001,Calculations!C2:C1001,B21) -> 10600 | G21: =IFERROR(AVERAGEIF(Calculations!C2:C1001,B21,Calculations!M2:M1001),0) -> 3117.2012
B22: Enterprise | C22: =COUNTIF(Calculations!C2:C1001,B22) -> 330 | D22: =COUNTIFS(Calculations!C2:C1001,B22,Calculations!G2:G1001,1) -> 57 | E22: =IFERROR(D22/C22,0) -> 0.17272727 | F22: =SUMIFS(Calculations!P2:P1001,Calculations!C2:C1001,B22) -> 28500 | G22: =IFERROR(AVERAGEIF(Calculations!C2:C1001,B22,Calculations!M2:M1001),0) -> 7592.4242
B27: ■ MONTHLY CHURN TREND (REPT Bar Chart)
B28: Month | C28: Churns | D28: Bar (scale: 1 █ = 1 churn)
B29: 2024-01 | C29: =COUNTIF(Calculations!Q2:Q1001,B29) -> 0 | D29: =IF(C29>0,REPT("█",MIN(C29,30))&" ["&C29&"]","No churn") -> No churn
B30: 2024-02 | C30: =COUNTIF(Calculations!Q2:Q1001,B30) -> 1 | D30: =IF(C30>0,REPT("█",MIN(C30,30))&" ["&C30&"]","No churn") -> █ [1]
B31: 2024-03 | C31: =COUNTIF(Calculations!Q2:Q1001,B31) -> 0 | D31: =IF(C31>0,REPT("█",MIN(C31,30))&" ["&C31&"]","No churn") -> No churn
B32: 2024-04 | C32: =COUNTIF(Calculations!Q2:Q1001,B32) -> 1 | D32: =IF(C32>0,REPT("█",MIN(C32,30))&" ["&C32&"]","No churn") -> █ [1]
B33: 2024-05 | C33: =COUNTIF(Calculations!Q2:Q1001,B33) -> 2 | D33: =IF(C33>0,REPT("█",MIN(C33,30))&" ["&C33&"]","No churn") -> ██ [2]
B34: 2024-06 | C34: =COUNTIF(Calculations!Q2:Q1001,B34) -> 5 | D34: =IF(C34>0,REPT("█",MIN(C34,30))&" ["&C34&"]","No churn") -> █████ [5]
B35: 2024-07 | C35: =COUNTIF(Calculations!Q2:Q1001,B35) -> 4 | D35: =IF(C35>0,REPT("█",MIN(C35,30))&" ["&C35&"]","No churn") -> ████ [4]
B36: 2024-08 | C36: =COUNTIF(Calculations!Q2:Q1001,B36) -> 4 | D36: =IF(C36>0,REPT("█",MIN(C36,30))&" ["&C36&"]","No churn") -> ████ [4]
B37: 2024-09 | C37: =COUNTIF(Calculations!Q2:Q1001,B37) -> 6 | D37: =IF(C37>0,REPT("█",MIN(C37,30))&" ["&C37&"]","No churn") -> ██████ [6]
B38: 2024-10 | C38: =COUNTIF(Calculations!Q2:Q1001,B38) -> 6 | D38: =IF(C38>0,REPT("█",MIN(C38,30))&" ["&C38&"]","No churn") -> ██████ [6]
B39: 2024-11 | C39: =COUNTIF(Calculations!Q2:Q1001,B39) -> 8 | D39: =IF(C39>0,REPT("█",MIN(C39,30))&" ["&C39&"]","No churn") -> ████████ [8]
B40: 2024-12 | C40: =COUNTIF(Calculations!Q2:Q1001,B40) -> 6 | D40: =IF(C40>0,REPT("█",MIN(C40,30))&" ["&C40&"]","No churn") -> ██████ [6]
B41: 2025-01 | C41: =COUNTIF(Calculations!Q2:Q1001,B41) -> 6 | D41: =IF(C41>0,REPT("█",MIN(C41,30))&" ["&C41&"]","No churn") -> ██████ [6]
B42: 2025-02 | C42: =COUNTIF(Calculations!Q2:Q1001,B42) -> 6 | D42: =IF(C42>0,REPT("█",MIN(C42,30))&" ["&C42&"]","No churn") -> ██████ [6]
B43: 2025-03 | C43: =COUNTIF(Calculations!Q2:Q1001,B43) -> 26 | D43: =IF(C43>0,REPT("█",MIN(C43,30))&" ["&C43&"]","No churn") -> ██████████████████████████ [26]
B44: 2025-04 | C44: =COUNTIF(Calculations!Q2:Q1001,B44) -> 23 | D44: =IF(C44>0,REPT("█",MIN(C44,30))&" ["&C44&"]","No churn") -> ███████████████████████ [23]
B45: 2025-05 | C45: =COUNTIF(Calculations!Q2:Q1001,B45) -> 23 | D45: =IF(C45>0,REPT("█",MIN(C45,30))&" ["&C45&"]","No churn") -> ███████████████████████ [23]
B46: 2025-06 | C46: =COUNTIF(Calculations!Q2:Q1001,B46) -> 41 | D46: =IF(C46>0,REPT("█",MIN(C46,30))&" ["&C46&"]","No churn") -> ██████████████████████████████ [41]
B49: ■ TOP 5 CHURN DRIVERS (Correlation-Based)
B50: Rank | C50: Driver | G50: Correlation | I50: Strength | K50: Recommended Action
B51: 1 | C51: Tenure Months | G51: =Correlation_Analysis!C5 -> -0.68160986 | I51: =Correlation_Analysis!E5 -> Strong | K51: Trigger early-engagement emails in months 1-3
B52: 2 | C52: Lifetime Value | G52: =Correlation_Analysis!C6 -> -0.32884608 | I52: =Correlation_Analysis!E6 -> Moderate | K52: Offer LTV-boost bundles; upsell at 3-month mark
B53: 3 | C53: Plan Type (Numeric) | G53: =Correlation_Analysis!C7 -> -0.0049630862 | I53: =Correlation_Analysis!E7 -> Weak | K53: Improve Basic-plan onboarding; offer upgrade incentives
B54: 4 | C54: Monthly Fee | G54: =Correlation_Analysis!C4 -> 0.00012085383 | I54: =Correlation_Analysis!E4 -> Weak | K54: Introduce flexible billing; discount annual plans
B55: 5 | C55: Acquisition Cost | G55: =Correlation_Analysis!C8 -> -0.0022577012 | I55: =Correlation_Analysis!E8 -> Weak | K55: Align sales promises with product capabilities
B59: ■ RETENTION INTERVENTION TRACKER
...

Sheet Customers Raw data
A1: customer_id | B1: signup_date | C1: plan_type | D1: monthly_fee | E1: acquisition_cost | F1: churn_date
A2: 1001 | B2: 2024-11-07 | C2: Basic | D2: 50 | E2: 30
A3: 1002 | B3: 2024-06-06 | C3: Basic | D3: 50 | E3: 30
A4: 1003 | B4: 2024-12-31 | C4: Basic | D4: 50 | E4: 30
A5: 1004 | B5: 2024-11-21 | C5: Pro | D5: 200 | E5: 100
A6: 1005 | B6: 2024-08-16 | C6: Pro | D6: 200 | E6: 100
A7: 1006 | B7: 2024-11-10 | C7: Basic | D7: 50 | E7: 30
A8: 1007 | B8: 2024-03-12 | C8: Enterprise | D8: 500 | E8: 200
A9: 1008 | B9: 2024-11-09 | C9: Pro | D9: 200 | E9: 100
A10: 1009 | B10: 2024-08-16 | C10: Pro | D10: 200 | E10: 100
A11: 1010 | B11: 2025-04-07 | C11: Pro | D11: 200 | E11: 100
A12: 1011 | B12: 2025-03-31 | C12: Basic | D12: 50 | E12: 30
A13: 1012 | B13: 2025-02-24 | C13: Enterprise | D13: 500 | E13: 200
... A20: 1019 | B20: 2024-06-29 | C20: Basic | D20: 50 | E20: 30
A21: 1020 | B21: 2024-10-13 | C21: Pro | D21: 200 | E21: 100 | F21: 2025-05-08
A22: 1021 | B22: 2024-04-29 | C22: Pro | D22: 200 | E22: 100 | F22: 2024-06-21
A23: 1022 | B23: 2024-03-22 | C23: Enterprise | D23: 500 | E23: 200
A24: 1023 | B24: 2024-12-15 | C24: Basic | D24: 50 | E24: 30 | F24: 2025-06-23
A25: 1024 | B25: 2024-10-22 | C25: Basic | D25: 50 | E25: 30
A26: 1025 | B26: 2024-03-13 | C26: Enterprise | D26: 500 | E26: 200
A27: 1026 | B27: 2025-03-27 | C27: Pro | D27: 200 | E27: 100 | F27: 2025-06-10
A28: 1027 | B28: 2024-06-12 | C28: Pro | D28: 200 | E28: 100
A29: 1028 | B29: 2025-01-13 | C29: Enterprise | D29: 500 | E29: 200
A30: 1029 | B30: 2025-06-25 | C30: Enterprise | D30: 500 | E30: 200
A31: 1030 | B31: 2024-11-18 | C31: Enterprise | D31: 500 | E31: 200
A32: 1031 | B32: 2024-04-08 | C32: Pro | D32: 200 | E32: 100 | F32: 2024-12-14
A33: 1032 | B33: 2025-02-04 | C33: Pro | D33: 200 | E33: 100
A34: 1033 | B34: 2025-03-07 | C34: Basic | D34: 50 | E34: 30
A35: 1034 | B35: 2024-04-06 | C35: Basic | D35: 50 | E35: 30 | F35: 2025-04-06
A36: 1035 | B36: 2024-07-31 | C36: Basic | D36: 50 | E36: 30 | F36: 2025-05-02
A37: 1036 | B37: 2024-05-07 | C37: Enterprise | D37: 500 | E37: 200
A38: 1037 | B38: 2024-11-30 | C38: Pro | D38: 200 | E38: 100
A39: 1038 | B39: 2024-01-28 | C39: Enterprise | D39: 500 | E39: 200
A40: 1039 | B40: 2025-04-22 | C40: Basic | D40: 50 | E40: 30
A41: 1040 | B41: 2024-05-16 | C41: Enterprise | D41: 500 | E41: 200
A42: 1041 | B42: 2024-06-21 | C42: Pro | D42: 200 | E42: 100
A43: 1042 | B43: 2024-04-18 | C43: Pro | D43: 200 | E43: 100 | F43: 2025-03-19
A44: 1043 | B44: 2025-01-27 | C44: Enterprise | D44: 500 | E44: 200 | F44: 2025-03-11
A45: 1044 | B45: 2025-02-28 | C45: Pro | D45: 200 | E45: 100
A46: 1045 | B46: 2025-06-30 | C46: Pro | D46: 200 | E46: 100
...

Sheet Revenue Raw data
A1: subscription_id | B1: customer_id | C1: month | D1: monthly_fee | E1: revenue_type | F1: amount
A2: S-1020-202410 | B2: 1020 | C2: 2024-10 | D2: 200 | E2: MRR | F2: 200
A3: S-1020-202411 | B3: 1020 | C3: 2024-11 | D3: 200 | E3: MRR | F3: 200
A4: S-1020-202412 | B4: 1020 | C4: 2024-12 | D4: 200 | E4: MRR | F4: 200
A5: S-1020-202501 | B5: 1020 | C5: 2025-01 | D5: 200 | E5: MRR | F5: 200
A6: S-1020-202502 | B6: 1020 | C6: 2025-02 | D6: 200 | E6: MRR | F6: 200
A7: S-1020-202503 | B7: 1020 | C7: 2025-03 | D7: 200 | E7: MRR | F7: 200
A8: S-1020-202504 | B8: 1020 | C8: 2025-04 | D8: 200 | E8: MRR | F8: 200
A9: S-1021-202404 | B9: 1021 | C9: 2024-04 | D9: 200 | E9: MRR | F9: 200
A10: S-1021-202405 | B10: 1021 | C10: 2024-05 | D10: 200 | E10: MRR | F10: 200
A11: S-1023-202412 | B11: 1023 | C11: 2024-12 | D11: 50 | E11: MRR | F11: 50
A12: S-1023-202501 | B12: 1023 | C12: 2025-01 | D12: 50 | E12: MRR | F12: 50
A13: S-1023-202502 | B13: 1023 | C13: 2025-02 | D13: 50 | E13: MRR | F13: 50
... A989: S-1999-202505 | B989: 1999 | C989: 2025-05 | D989: 500 | E989: MRR | F989: 500

Sheet Calculations
A1: customer_id | B1: signup_date | C1: plan_type | D1: monthly_fee | E1: acquisition_cost | F1: churn_date | G1: is_churned | H1: churn_year | I1: churn_month | J1: signup_year | K1: signup_month | L1: tenure_months | M1: lifetime_value | N1: plan_numeric | O1: at_risk_flag | P1: mrr_lost | Q1: churn_cohort
A2: ='Customers Raw data'!A2 -> 1001 | B2: ='Customers Raw data'!B2 -> 2024-11-07 | C2: ='Customers Raw data'!C2 -> Basic | D2: ='Customers Raw data'!D2 -> 50 | E2: ='Customers Raw data'!E2 -> 30 | F2: ='Customers Raw data'!F2 -> 0 | G2: =IF('Customers Raw data'!F2<>"",1,0) -> 0 | H2: =IF('Customers Raw data'!F2<>"",YEAR(DATEVALUE('Customers Raw data'!F2)),"") | I2: =IF('Customers Raw data'!F2<>"",MONTH(DATEVALUE('Customers Raw data'!F2)),"") | J2: =YEAR(DATEVALUE('Customers Raw data'!B2)) -> 2024 | K2: =MONTH(DATEVALUE('Customers Raw data'!B2)) -> 11 | L2: =IF('Customers Raw data'!F2<>"",DATEDIF(DATEVALUE('Customers Raw data'!B2),DATEVALUE('Customers Raw data'!F2),"M"),DATEDIF(DATEVALUE('Customers Raw data'!B2),TODAY(),"M")) -> 17 | M2: =D2*L2 -> 850 | N2: =IF(C2="Basic",1,IF(C2="Pro",2,IF(C2="Enterprise",3,0))) -> 1 | O2: =IF(AND(G2=1,L2<6),1,0) -> 0 | P2: =IF(G2=1,D2,0) -> 0 | Q2: =IF(F2<>"",TEXT(DATEVALUE(F2),"YYYY-MM"),"") -> #VALUE!
A3: ='Customers Raw data'!A3 -> 1002 | B3: ='Customers Raw data'!B3 -> 2024-06-06 | C3: ='Customers Raw data'!C3 -> Basic | D3: ='Customers Raw data'!D3 -> 50 | E3: ='Customers Raw data'!E3 -> 30 | F3: ='Customers Raw data'!F3 -> 0 | G3: =IF('Customers Raw data'!F3<>"",1,0) -> 0 | H3: =IF('Customers Raw data'!F3<>"",YEAR(DATEVALUE('Customers Raw data'!F3)),"") | I3: =IF('Customers Raw data'!F3<>"",MONTH(DATEVALUE('Customers Raw data'!F3)),"") | J3: =YEAR(DATEVALUE('Customers Raw data'!B3)) -> 2024 | K3: =MONTH(DATEVALUE('Customers Raw data'!B3)) -> 6 | L3: =IF('Customers Raw data'!F3<>"",DATEDIF(DATEVALUE('Customers Raw data'!B3),DATEVALUE('Customers Raw data'!F3),"M"),DATEDIF(DATEVALUE('Customers Raw data'!B3),TODAY(),"M")) -> 22 | M3: =D3*L3 -> 1100 | N3: =IF(C3="Basic",1,IF(C3="Pro",2,IF(C3="Enterprise",3,0))) -> 1 | O3: =IF(AND(G3=1,L3<6),1,0) -> 0 | P3: =IF(G3=1,D3,0) -> 0 | Q3: =IF(F3<>"",TEXT(DATEVALUE(F3),"YYYY-MM"),"") -> #VALUE!
A4: ='Customers Raw data'!A4 -> 1003 | B4: ='Customers Raw data'!B4 -> 2024-12-31 | C4: ='Customers Raw data'!C4 -> Basic | D4: ='Customers Raw data'!D4 -> 50 | E4: ='Customers Raw data'!E4 -> 30 | F4: ='Customers Raw data'!F4 -> 0 | G4: =IF('Customers Raw data'!F4<>"",1,0) -> 0 | H4: =IF('Customers Raw data'!F4<>"",YEAR(DATEVALUE('Customers Raw data'!F4)),"") | I4: =IF('Customers Raw data'!F4<>"",MONTH(DATEVALUE('Customers Raw data'!F4)),"") | J4: =YEAR(DATEVALUE('Customers Raw data'!B4)) -> 2024 | K4: =MONTH(DATEVALUE('Customers Raw data'!B4)) -> 12 | L4: =IF('Customers Raw data'!F4<>"",DATEDIF(DATEVALUE('Customers Raw data'!B4),DATEVALUE('Customers Raw data'!F4),"M"),DATEDIF(DATEVALUE('Customers Raw data'!B4),TODAY(),"M")) -> 15 | M4: =D4*L4 -> 750 | N4: =IF(C4="Basic",1,IF(C4="Pro",2,IF(C4="Enterprise",3,0))) -> 1 | O4: =IF(AND(G4=1,L4<6),1,0) -> 0 | P4: =IF(G4=1,D4,0) -> 0 | Q4: =IF(F4<>"",TEXT(DATEVALUE(F4),"YYYY-MM"),"") -> #VALUE!
A5: ='Customers Raw data'!A5 -> 1004 | B5: ='Customers Raw data'!B5 -> 2024-11-21 | C5: ='Customers Raw data'!C5 -> Pro | D5: ='Customers Raw data'!D5 -> 200 | E5: ='Customers Raw data'!E5 -> 100 | F5: ='Customers Raw data'!F5 -> 0 | G5: =IF('Customers Raw data'!F5<>"",1,0) -> 0 | H5: =IF('Customers Raw data'!F5<>"",YEAR(DATEVALUE('Customers Raw data'!F5)),"") | I5: =IF('Customers Raw data'!F5<>"",MONTH(DATEVALUE('Customers Raw data'!F5)),"") | J5: =YEAR(DATEVALUE('Customers Raw data'!B5)) -> 2024 | K5: =MONTH(DATEVALUE('Customers Raw data'!B5)) -> 11 | L5: =IF('Customers Raw data'!F5<>"",DATEDIF(DATEVALUE('Customers Raw data'!B5),DATEVALUE('Customers Raw data'!F5),"M"),DATEDIF(DATEVALUE('Customers Raw data'!B5),TODAY(),"M")) -> 16 | M5: =D5*L5 -> 3200 | N5: =IF(C5="Basic",1,IF(C5="Pro",2,IF(C5="Enterprise",3,0))) -> 2 | O5: =IF(AND(G5=1,L5<6),1,0) -> 0 | P5: =IF(G5=1,D5,0) -> 0 | Q5: =IF(F5<>"",TEXT(DATEVALUE(F5),"YYYY-MM"),"") -> #VALUE!
A6: ='Customers Raw data'!A6 -> 1005 | B6: ='Customers Raw data'!B6 -> 2024-08-16 | C6: ='Customers Raw data'!C6 -> Pro | D6: ='Customers Raw data'!D6 -> 200 | E6: ='Customers Raw data'!E6 -> 100 | F6: ='Customers Raw data'!F6 -> 0 | G6: =IF('Customers Raw data'!F6<>"",1,0) -> 0 | H6: =IF('Customers Raw data'!F6<>"",YEAR(DATEVALUE('Customers Raw data'!F6)),"") | I6: =IF('Customers Raw data'!F6<>"",MONTH(DATEVALUE('Customers Raw data'!F6)),"") | J6: =YEAR(DATEVALUE('Customers Raw data'!B6)) -> 2024 | K6: =MONTH(DATEVALUE('Customers Raw data'!B6)) -> 8 | L6: =IF('Customers Raw data'!F6<>"",DATEDIF(DATEVALUE('Customers Raw data'!B6),DATEVALUE('Customers Raw data'!F6),"M"),DATEDIF(DATEVALUE('Customers Raw data'!B6),TODAY(),"M")) -> 19 | M6: =D6*L6 -> 3800 | N6: =IF(C6="Basic",1,IF(C6="Pro",2,IF(C6="Enterprise",3,0))) -> 2 | O6: =IF(AND(G6=1,L6<6),1,0) -> 0 | P6: =IF(G6=1,D6,0) -> 0 | Q6: =IF(F6<>"",TEXT(DATEVALUE(F6),"YYYY-MM"),"") -> #VALUE!
A7: ='Customers Raw data'!A7 -> 1006 | B7: ='Customers Raw data'!B7 -> 2024-11-10 | C7: ='Customers Raw data'!C7 -> Basic | D7: ='Customers Raw data'!D7 -> 50 | E7: ='Customers Raw data'!E7 -> 30 | F7: ='Customers Raw data'!F7 -> 0 | G7: =IF('Customers Raw data'!F7<>"",1,0) -> 0 | H7: =IF('Customers Raw data'!F7<>"",YEAR(DATEVALUE('Customers Raw data'!F7)),"") | I7: =IF('Customers Raw data'!F7<>"",MONTH(DATEVALUE('Customers Raw data'!F7)),"") | J7: =YEAR(DATEVALUE('Customers Raw data'!B7)) -> 2024 | K7: =MONTH(DATEVALUE('Customers Raw data'!B7)) -> 11 | L7: =IF('Customers Raw data'!F7<>"",DATEDIF(DATEVALUE('Customers Raw data'!B7),DATEVALUE('Customers Raw data'!F7),"M"),DATEDIF(DATEVALUE('Customers Raw data'!B7),TODAY(),"M")) -> 16 | M7: =D7*L7 -> 800 | N7: =IF(C7="Basic",1,IF(C7="Pro",2,IF(C7="Enterprise",3,0))) -> 1 | O7: =IF(AND(G7=1,L7<6),1,0) -> 0 | P7: =IF(G7=1,D7,0) -> 0 | Q7: =IF(F7<>"",TEXT(DATEVALUE(F7),"YYYY-MM"),"") -> #VALUE!
A8: ='Customers Raw data'!A8 -> 1007 | B8: ='Customers Raw data'!B8 -> 2024-03-12 | C8: ='Customers Raw data'!C8 -> Enterprise | D8: ='Customers Raw data'!D8 -> 500 | E8: ='Customers Raw data'!E8 -> 200 | F8: ='Customers Raw data'!F8 -> 0 | G8: =IF('Customers Raw data'!F8<>"",1,0) -> 0 | H8: =IF('Customers Raw data'!F8<>"",YEAR(DATEVALUE('Customers Raw data'!F8)),"") | I8: =IF('Customers Raw data'!F8<>"",MONTH(DATEVALUE('Customers Raw data'!F8)),"") | J8: =YEAR(DATEVALUE('Customers Raw data'!B8)) -> 2024 | K8: =MONTH(DATEVALUE('Customers Raw data'!B8)) -> 3 | L8: =IF('Customers Raw data'!F8<>"",DATEDIF(DATEVALUE('Customers Raw data'!B8),DATEVALUE('Customers Raw data'!F8),"M"),DATEDIF(DATEVALUE('Customers Raw data'!B8),TODAY(),"M")) -> 24 | M8: =D8*L8 -> 12000 | N8: =IF(C8="Basic",1,IF(C8="Pro",2,IF(C8="Enterprise",3,0))) -> 3 | O8: =IF(AND(G8=1,L8<6),1,0) -> 0 | P8: =IF(G8=1,D8,0) -> 0 | Q8: =IF(F8<>"",TEXT(DATEVALUE(F8),"YYYY-MM"),"") -> #VALUE!
A9: ='Customers Raw data'!A9 -> 1008 | B9: ='Customers Raw data'!B9 -> 2024-11-09 | C9: ='Customers Raw data'!C9 -> Pro | D9: ='Customers Raw data'!D9 -> 200 | E9: ='Customers Raw data'!E9 -> 100 | F9: ='Customers Raw data'!F9 -> 0 | G9: =IF('Customers Raw data'!F9<>"",1,0) -> 0 | H9: =IF('Customers Raw data'!F9<>"",YEAR(DATEVALUE('Customers Raw data'!F9)),"") | I9: =IF('Customers Raw data'!F9<>"",MONTH(DATEVALUE('Customers Raw data'!F9)),"") | J9: =YEAR(DATEVALUE('Customers Raw data'!B9)) -> 2024 | K9: =MONTH(DATEVALUE('Customers Raw data'!B9)) -> 11 | L9: =IF('Customers Raw data'!F9<>"",DATEDIF(DATEVALUE('Customers Raw data'!B9),DATEVALUE('Customers Raw data'!F9),"M"),DATEDIF(DATEVALUE('Customers Raw data'!B9),TODAY(),"M")) -> 16 | M9: =D9*L9 -> 3200 | N9: =IF(C9="Basic",1,IF(C9="Pro",2,IF(C9="Enterprise",3,0))) -> 2 | O9: =IF(AND(G9=1,L9<6),1,0) -> 0 | P9: =IF(G9=1,D9,0) -> 0 | Q9: =IF(F9<>"",TEXT(DATEVALUE(F9),"YYYY-MM"),"") -> #VALUE!
A10: ='Customers Raw data'!A10 -> 1009 | B10: ='Customers Raw data'!B10 -> 2024-08-16 | C10: ='Customers Raw data'!C10 -> Pro | D10: ='Customers Raw data'!D10 -> 200 | E10: ='Customers Raw data'!E10 -> 100 | F10: ='Customers Raw data'!F10 -> 0 | G10: =IF('Customers Raw data'!F10<>"",1,0) -> 0 | H10: =IF('Customers Raw data'!F10<>"",YEAR(DATEVALUE('Customers Raw data'!F10)),"") | I10: =IF('Customers Raw data'!F10<>"",MONTH(DATEVALUE('Customers Raw data'!F10)),"") | J10: =YEAR(DATEVALUE('Customers Raw data'!B10)) -> 2024 | K10: =MONTH(DATEVALUE('Customers Raw data'!B10)) -> 8 | L10: =IF('Customers Raw data'!F10<>"",DATEDIF(DATEVALUE('Customers Raw data'!B10),DATEVALUE('Customers Raw data'!F10),"M"),DATEDIF(DATEVALUE('Customers Raw data'!B10),TODAY(),"M")) -> 19 | M10: =D10*L10 -> 3800 | N10: =IF(C10="Basic",1,IF(C10="Pro",2,IF(C10="Enterprise",3,0))) -> 2 | O10: =IF(AND(G10=1,L10<6),1,0) -> 0 | P10: =IF(G10=1,D10,0) -> 0 | Q10: =IF(F10<>"",TEXT(DATEVALUE(F10),"YYYY-MM"),"") -> #VALUE!
A11: ='Customers Raw data'!A11 -> 1010 | B11: ='Customers Raw data'!B11 -> 2025-04-07 | C11: ='Customers Raw data'!C11 -> Pro | D11: ='Customers Raw data'!D11 -> 200 | E11: ='Customers Raw data'!E11 -> 100 | F11: ='Customers Raw data'!F11 -> 0 | G11: =IF('Customers Raw data'!F11<>"",1,0) -> 0 | H11: =IF('Customers Raw data'!F11<>"",YEAR(DATEVALUE('Customers Raw data'!F11)),"") | I11: =IF('Customers Raw data'!F11<>"",MONTH(DATEVALUE('Customers Raw data'!F11)),"") | J11: =YEAR(DATEVALUE('Customers Raw data'!B11)) -> 2025 | K11: =MONTH(DATEVALUE('Customers Raw data'!B11)) -> 4 | L11: =IF('Customers Raw data'!F11<>"",DATEDIF(DATEVALUE('Customers Raw data'!B11),DATEVALUE('Customers Raw data'!F11),"M"),DATEDIF(DATEVALUE('Customers Raw data'!B11),TODAY(),"M")) -> 12 | M11: =D11*L11 -> 2400 | N11: =IF(C11="Basic",1,IF(C11="Pro",2,IF(C11="Enterprise",3,0))) -> 2 | O11: =IF(AND(G11=1,L11<6),1,0) -> 0 | P11: =IF(G11=1,D11,0) -> 0 | Q11: =IF(F11<>"",TEXT(DATEVALUE(F11),"YYYY-MM"),"") -> #VALUE!
A12: ='Customers Raw data'!A12 -> 1011 | B12: ='Customers Raw data'!B12 -> 2025-03-31 | C12: ='Customers Raw data'!C12 -> Basic | D12: ='Customers Raw data'!D12 -> 50 | E12: ='Customers Raw data'!E12 -> 30 | F12: ='Customers Raw data'!F12 -> 0 | G12: =IF('Customers Raw data'!F12<>"",1,0) -> 0 | H12: =IF('Customers Raw data'!F12<>"",YEAR(DATEVALUE('Customers Raw data'!F12)),"") | I12: =IF('Customers Raw data'!F12<>"",MONTH(DATEVALUE('Customers Raw data'!F12)),"") | J12: =YEAR(DATEVALUE('Customers Raw data'!B12)) -> 2025 | K12: =MONTH(DATEVALUE('Customers Raw data'!B12)) -> 3 | L12: =IF('Customers Raw data'!F12<>"",DATEDIF(DATEVALUE('Customers Raw data'!B12),DATEVALUE('Customers Raw data'!F12),"M"),DATEDIF(DATEVALUE('Customers Raw data'!B12),TODAY(),"M")) -> 12 | M12: =D12*L12 -> 600 | N12: =IF(C12="Basic",1,IF(C12="Pro",2,IF(C12="Enterprise",3,0))) -> 1 | O12: =IF(AND(G12=1,L12<6),1,0) -> 0 | P12: =IF(G12=1,D12,0) -> 0 | Q12: =IF(F12<>"",TEXT(DATEVALUE(F12),"YYYY-MM"),"") -> #VALUE!
A13: ='Customers Raw data'!A13 -> 1012 | B13: ='Customers Raw data'!B13 -> 2025-02-24 | C13: ='Customers Raw data'!C13 -> Enterprise | D13: ='Customers Raw data'!D13 -> 500 | E13: ='Customers Raw data'!E13 -> 200 | F13: ='Customers Raw data'!F13 -> 0 | G13: =IF('Customers Raw data'!F13<>"",1,0) -> 0 | H13: =IF('Customers Raw data'!F13<>"",YEAR(DATEVALUE('Customers Raw data'!F13)),"") | I13: =IF('Customers Raw data'!F13<>"",MONTH(DATEVALUE('Customers Raw data'!F13)),"") | J13: =YEAR(DATEVALUE('Customers Raw data'!B13)) -> 2025 | K13: =MONTH(DATEVALUE('Customers Raw data'!B13)) -> 2 | L13: =IF('Customers Raw data'!F13<>"",DATEDIF(DATEVALUE('Customers Raw data'!B13),DATEVALUE('Customers Raw data'!F13),"M"),DATEDIF(DATEVALUE('Customers Raw data'!B13),TODAY(),"M")) -> 13 | M13: =D13*L13 -> 6500 | N13: =IF(C13="Basic",1,IF(C13="Pro",2,IF(C13="Enterprise",3,0))) -> 3 | O13: =IF(AND(G13=1,L13<6),1,0) -> 0 | P13: =IF(G13=1,D13,0) -> 0 | Q13: =IF(F13<>"",TEXT(DATEVALUE(F13),"YYYY-MM"),"") -> #VALUE!
... A1001: ='Customers Raw data'!A1001 -> 2000 | B1001: ='Customers Raw data'!B1001 -> 2024-07-24 | C1001: ='Customers Raw data'!C1001 -> Pro | D1001: ='Customers Raw data'!D1001 -> 200 | E1001: ='Customers Raw data'!E1001 -> 100 | F1001: ='Customers Raw data'!F1001 -> 0 | G1001: =IF('Customers Raw data'!F1001<>"",1,0) -> 0 | H1001: =IF('Customers Raw data'!F1001<>"",YEAR(DATEVALUE('Customers Raw data'!F1001)),"") | I1001: =IF('Customers Raw data'!F1001<>"",MONTH(DATEVALUE('Customers Raw data'!F1001)),"") | J1001: =YEAR(DATEVALUE('Customers Raw data'!B1001)) -> 2024 | K1001: =MONTH(DATEVALUE('Customers Raw data'!B1001)) -> 7 | L1001: =IF('Customers Raw data'!F1001<>"",DATEDIF(DATEVALUE('Customers Raw data'!B1001),DATEVALUE('Customers Raw data'!F1001),"M"),DATEDIF(DATEVALUE('Customers Raw data'!B1001),TODAY(),"M")) -> 20 | M1001: =D1001*L1001 -> 4000 | N1001: =IF(C1001="Basic",1,IF(C1001="Pro",2,IF(C1001="Enterprise",3,0))) -> 2 | O1001: =IF(AND(G1001=1,L1001<6),1,0) -> 0 | P1001: =IF(G1001=1,D1001,0) -> 0 | Q1001: =IF(F1001<>"",TEXT(DATEVALUE(F1001),"YYYY-MM"),"") -> #VALUE!

Sheet Descriptive Statistics
A1: DESCRIPTIVE STATISTICS – Customer Churn Analysis
A3: MONTHLY FEE (D col = Calculations!D)
A4: Metric | B4: Formula | C4: Result
A5: Count | B5: ="=COUNT(Calculations!D2:Calculations!D1001)" -> =COUNT(Calculations!D2:Calculations!D1001) | C5: =COUNT(Calculations!D2:D1001) -> 1000
A6: Sum | B6: ="=SUM(Calculations!D2:Calculations!D1001)" -> =SUM(Calculations!D2:Calculations!D1001) | C6: =SUM(Calculations!D2:D1001) -> 249950
A7: Mean | B7: ="=AVERAGE(Calculations!D2:Calculations!D1001)" -> =AVERAGE(Calculations!D2:Calculations!D1001) | C7: =AVERAGE(Calculations!D2:D1001) -> 249.95
A8: Median | B8: ="=MEDIAN(Calculations!D2:Calculations!D1001)" -> =MEDIAN(Calculations!D2:Calculations!D1001) | C8: =MEDIAN(Calculations!D2:D1001) -> 200
A9: Std Dev | B9: ="=STDEV(Calculations!D2:Calculations!D1001)" -> =STDEV(Calculations!D2:Calculations!D1001) | C9: =STDEV(Calculations!D2:D1001) -> 186.00294
A10: Min | B10: ="=MIN(Calculations!D2:Calculations!D1001)" -> =MIN(Calculations!D2:Calculations!D1001) | C10: =MIN(Calculations!D2:D1001) -> 50
A11: Max | B11: ="=MAX(Calculations!D2:Calculations!D1001)" -> =MAX(Calculations!D2:Calculations!D1001) | C11: =MAX(Calculations!D2:D1001) -> 500
A12: Mode | B12: ="=MODE.SNGL(Calculations!D2:Calculations!D1001)" -> =MODE.SNGL(Calculations!D2:Calculations!D1001) | C12: =MODE(Calculations!D2:D1001) -> 200
A13: TENURE MONTHS (L col = Calculations!L)
A14: Metric | B14: Formula | C14: Result
A15: Count | B15: ="=COUNT(Calculations!L2:Calculations!L1001)" -> =COUNT(Calculations!L2:Calculations!L1001) | C15: =COUNT(Calculations!L2:L1001) -> 1000
A16: Sum | B16: ="=SUM(Calculations!L2:Calculations!L1001)" -> =SUM(Calculations!L2:Calculations!L1001) | C16: =SUM(Calculations!L2:L1001) -> 15408
A17: Mean | B17: ="=AVERAGE(Calculations!L2:Calculations!L1001)" -> =AVERAGE(Calculations!L2:Calculations!L1001) | C17: =AVERAGE(Calculations!L2:L1001) -> 15.408
A18: Median | B18: ="=MEDIAN(Calculations!L2:Calculations!L1001)" -> =MEDIAN(Calculations!L2:Calculations!L1001) | C18: =MEDIAN(Calculations!L2:L1001) -> 16
A19: Std Dev | B19: ="=STDEV(Calculations!L2:Calculations!L1001)" -> =STDEV(Calculations!L2:Calculations!L1001) | C19: =STDEV(Calculations!L2:L1001) -> 6.9513925
A20: Min | B20: ="=MIN(Calculations!L2:Calculations!L1001)" -> =MIN(Calculations!L2:Calculations!L1001) | C20: =MIN(Calculations!L2:L1001) -> 0
A21: Max | B21: ="=MAX(Calculations!L2:Calculations!L1001)" -> =MAX(Calculations!L2:Calculations!L1001) | C21: =MAX(Calculations!L2:L1001) -> 27
A22: Mode | B22: ="=MODE.SNGL(Calculations!L2:Calculations!L1001)" -> =MODE.SNGL(Calculations!L2:Calculations!L1001) | C22: =MODE(Calculations!L2:L1001) -> 12
A23: LIFETIME VALUE (M col = Calculations!M)
A24: Metric | B24: Formula | C24: Result
A25: Count | B25: ="=COUNT(Calculations!M2:Calculations!M1001)" -> =COUNT(Calculations!M2:Calculations!M1001) | C25: =COUNT(Calculations!M2:M1001) -> 1000
A26: Sum | B26: ="=SUM(Calculations!M2:Calculations!M1001)" -> =SUM(Calculations!M2:Calculations!M1001) | C26: =SUM(Calculations!M2:M1001) -> 3827250
A27: Mean | B27: ="=AVERAGE(Calculations!M2:Calculations!M1001)" -> =AVERAGE(Calculations!M2:Calculations!M1001) | C27: =AVERAGE(Calculations!M2:M1001) -> 3827.25
A28: Median | B28: ="=MEDIAN(Calculations!M2:Calculations!M1001)" -> =MEDIAN(Calculations!M2:Calculations!M1001) | C28: =MEDIAN(Calculations!M2:M1001) -> 2800
A29: Std Dev | B29: ="=STDEV(Calculations!M2:Calculations!M1001)" -> =STDEV(Calculations!M2:Calculations!M1001) | C29: =STDEV(Calculations!M2:M1001) -> 3547.0984
A30: Min | B30: ="=MIN(Calculations!M2:Calculations!M1001)" -> =MIN(Calculations!M2:Calculations!M1001) | C30: =MIN(Calculations!M2:M1001) -> 0
A31: Max | B31: ="=MAX(Calculations!M2:Calculations!M1001)" -> =MAX(Calculations!M2:Calculations!M1001) | C31: =MAX(Calculations!M2:M1001) -> 13500
A32: Mode | B32: ="=MODE.SNGL(Calculations!M2:Calculations!M1001)" -> =MODE.SNGL(Calculations!M2:Calculations!M1001) | C32: =MODE(Calculations!M2:M1001) -> 5000
A33: ACQUISITION COST (E col = Calculations!E)
A34: Metric | B34: Formula | C34: Result
A35: Count | B35: ="=COUNT(Calculations!E2:Calculations!E1001)" -> =COUNT(Calculations!E2:Calculations!E1001) | C35: =COUNT(Calculations!E2:E1001) -> 1000
A36: Sum | B36: ="=SUM(Calculations!E2:Calculations!E1001)" -> =SUM(Calculations!E2:Calculations!E1001) | C36: =SUM(Calculations!E2:E1001) -> 110110
A37: Mean | B37: ="=AVERAGE(Calculations!E2:Calculations!E1001)" -> =AVERAGE(Calculations!E2:Calculations!E1001) | C37: =AVERAGE(Calculations!E2:E1001) -> 110.11
A38: Median | B38: ="=MEDIAN(Calculations!E2:Calculations!E1001)" -> =MEDIAN(Calculations!E2:Calculations!E1001) | C38: =MEDIAN(Calculations!E2:E1001) -> 100
A39: Std Dev | B39: ="=STDEV(Calculations!E2:Calculations!E1001)" -> =STDEV(Calculations!E2:Calculations!E1001) | C39: =STDEV(Calculations!E2:E1001) -> 69.317334
A40: Min | B40: ="=MIN(Calculations!E2:Calculations!E1001)" -> =MIN(Calculations!E2:Calculations!E1001) | C40: =MIN(Calculations!E2:E1001) -> 30
A41: Max | B41: ="=MAX(Calculations!E2:Calculations!E1001)" -> =MAX(Calculations!E2:Calculations!E1001) | C41: =MAX(Calculations!E2:E1001) -> 200
...

Sheet Segmentation
A1: SEGMENTATION ANALYSIS – By Plan Type
A3: Plan | B3: Total Customers | C3: Churned | D3: Active | E3: Churn Rate | F3: Avg MRR | G3: Total LTV | H3: Avg Tenure | I3: MRR Lost
A4: Basic | B4: =COUNTIF(Calculations!C2:C1001,A4) -> 327 | C4: =COUNTIFS(Calculations!C2:C1001,A4,Calculations!G2:G1001,1) -> 58 | D4: =B4-C4 -> 269 | E4: =IFERROR(C4/B4,0) -> 0.17737003 | F4: =AVERAGEIF(Calculations!C2:C1001,A4,Calculations!D2:D1001) -> 50 | G4: =SUMIF(Calculations!C2:C1001,A4,Calculations!M2:M1001) -> 252550 | H4: =AVERAGEIF(Calculations!C2:C1001,A4,Calculations!L2:L1001) -> 15.446483 | I4: =SUMIFS(Calculations!P2:P1001,Calculations!C2:C1001,A4) -> 2900
A5: Pro | B5: =COUNTIF(Calculations!C2:C1001,A5) -> 343 | C5: =COUNTIFS(Calculations!C2:C1001,A5,Calculations!G2:G1001,1) -> 53 | D5: =B5-C5 -> 290 | E5: =IFERROR(C5/B5,0) -> 0.15451895 | F5: =AVERAGEIF(Calculations!C2:C1001,A5,Calculations!D2:D1001) -> 200 | G5: =SUMIF(Calculations!C2:C1001,A5,Calculations!M2:M1001) -> 1069200 | H5: =AVERAGEIF(Calculations!C2:C1001,A5,Calculations!L2:L1001) -> 15.586006 | I5: =SUMIFS(Calculations!P2:P1001,Calculations!C2:C1001,A5) -> 10600
A6: Enterprise | B6: =COUNTIF(Calculations!C2:C1001,A6) -> 330 | C6: =COUNTIFS(Calculations!C2:C1001,A6,Calculations!G2:G1001,1) -> 57 | D6: =B6-C6 -> 273 | E6: =IFERROR(C6/B6,0) -> 0.17272727 | F6: =AVERAGEIF(Calculations!C2:C1001,A6,Calculations!D2:D1001) -> 500 | G6: =SUMIF(Calculations!C2:C1001,A6,Calculations!M2:M1001) -> 2505500 | H6: =AVERAGEIF(Calculations!C2:C1001,A6,Calculations!L2:L1001) -> 15.184848 | I6: =SUMIFS(Calculations!P2:P1001,Calculations!C2:C1001,A6) -> 28500
A7: TOTAL | B7: =SUM(B4:B6) -> 1000 | C7: =SUM(C4:C6) -> 168 | D7: =SUM(D4:D6) -> 832 | E7: =IFERROR(C7/B7,0) -> 0.168 | F7: =SUM(F4:F6) -> 750 | G7: =SUM(G4:G6) -> 3827250 | H7: =IFERROR(AVERAGE(H4:H6),0) -> 15.405779 | I7: =SUM(I4:I6) -> 42000

Sheet Trend Analysis
A1: MONTHLY CHURN TREND ANALYSIS
A3: Month | B3: Churns | C3: New Signups | D3: MRR Lost | E3: MRR Gained | F3: Net MRR Change | G3: Trend Bar
A4: 2024-01 | B4: =COUNTIF(Calculations!Q2:Q1001,A4) -> 0 | C4: =SUMPRODUCT((TEXT(DATEVALUE('Customers Raw data'!B2:B1001),"YYYY-MM")=A4)*1) -> 57 | D4: =SUMIF(Calculations!Q2:Q1001,A4,Calculations!P2:P1001) -> 0 | E4: =SUMPRODUCT((TEXT(DATEVALUE('Customers Raw data'!B2:B1001),"YYYY-MM")=A4)*'Customers Raw data'!D2:D1001) -> 13650 | F4: =E4-D4 -> 13650 | G4: =IF(B4>0,REPT("█",MIN(B4,20)),"–") -> –
A5: 2024-02 | B5: =COUNTIF(Calculations!Q2:Q1001,A5) -> 1 | C5: =SUMPRODUCT((TEXT(DATEVALUE('Customers Raw data'!B2:B1001),"YYYY-MM")=A5)*1) -> 53 | D5: =SUMIF(Calculations!Q2:Q1001,A5,Calculations!P2:P1001) -> 50 | E5: =SUMPRODUCT((TEXT(DATEVALUE('Customers Raw data'!B2:B1001),"YYYY-MM")=A5)*'Customers Raw data'!D2:D1001) -> 14200 | F5: =E5-D5 -> 14150 | G5: =IF(B5>0,REPT("█",MIN(B5,20)),"–") -> █
A6: 2024-03 | B6: =COUNTIF(Calculations!Q2:Q1001,A6) -> 0 | C6: =SUMPRODUCT((TEXT(DATEVALUE('Customers Raw data'!B2:B1001),"YYYY-MM")=A6)*1) -> 63 | D6: =SUMIF(Calculations!Q2:Q1001,A6,Calculations!P2:P1001) -> 0 | E6: =SUMPRODUCT((TEXT(DATEVALUE('Customers Raw data'!B2:B1001),"YYYY-MM")=A6)*'Customers Raw data'!D2:D1001) -> 16050 | F6: =E6-D6 -> 16050 | G6: =IF(B6>0,REPT("█",MIN(B6,20)),"–") -> –
A7: 2024-04 | B7: =COUNTIF(Calculations!Q2:Q1001,A7) -> 1 | C7: =SUMPRODUCT((TEXT(DATEVALUE('Customers Raw data'!B2:B1001),"YYYY-MM")=A7)*1) -> 50 | D7: =SUMIF(Calculations!Q2:Q1001,A7,Calculations!P2:P1001) -> 500 | E7: =SUMPRODUCT((TEXT(DATEVALUE('Customers Raw data'!B2:B1001),"YYYY-MM")=A7)*'Customers Raw data'!D2:D1001) -> 10600 | F7: =E7-D7 -> 10100 | G7: =IF(B7>0,REPT("█",MIN(B7,20)),"–") -> █
A8: 2024-05 | B8: =COUNTIF(Calculations!Q2:Q1001,A8) -> 2 | C8: =SUMPRODUCT((TEXT(DATEVALUE('Customers Raw data'!B2:B1001),"YYYY-MM")=A8)*1) -> 52 | D8: =SUMIF(Calculations!Q2:Q1001,A8,Calculations!P2:P1001) -> 700 | E8: =SUMPRODUCT((TEXT(DATEVALUE('Customers Raw data'!B2:B1001),"YYYY-MM")=A8)*'Customers Raw data'!D2:D1001) -> 11600 | F8: =E8-D8 -> 10900 | G8: =IF(B8>0,REPT("█",MIN(B8,20)),"–") -> ██
A9: 2024-06 | B9: =COUNTIF(Calculations!Q2:Q1001,A9) -> 5 | C9: =SUMPRODUCT((TEXT(DATEVALUE('Customers Raw data'!B2:B1001),"YYYY-MM")=A9)*1) -> 51 | D9: =SUMIF(Calculations!Q2:Q1001,A9,Calculations!P2:P1001) -> 1000 | E9: =SUMPRODUCT((TEXT(DATEVALUE('Customers Raw data'!B2:B1001),"YYYY-MM")=A9)*'Customers Raw data'!D2:D1001) -> 11100 | F9: =E9-D9 -> 10100 | G9: =IF(B9>0,REPT("█",MIN(B9,20)),"–") -> █████
A10: 2024-07 | B10: =COUNTIF(Calculations!Q2:Q1001,A10) -> 4 | C10: =SUMPRODUCT((TEXT(DATEVALUE('Customers Raw data'!B2:B1001),"YYYY-MM")=A10)*1) -> 49 | D10: =SUMIF(Calculations!Q2:Q1001,A10,Calculations!P2:P1001) -> 500 | E10: =SUMPRODUCT((TEXT(DATEVALUE('Customers Raw data'!B2:B1001),"YYYY-MM")=A10)*'Customers Raw data'!D2:D1001) -> 14600 | F10: =E10-D10 -> 14100 | G10: =IF(B10>0,REPT("█",MIN(B10,20)),"–") -> ████
A11: 2024-08 | B11: =COUNTIF(Calculations!Q2:Q1001,A11) -> 4 | C11: =SUMPRODUCT((TEXT(DATEVALUE('Customers Raw data'!B2:B1001),"YYYY-MM")=A11)*1) -> 52 | D11: =SUMIF(Calculations!Q2:Q1001,A11,Calculations!P2:P1001) -> 950 | E11: =SUMPRODUCT((TEXT(DATEVALUE('Customers Raw data'!B2:B1001),"YYYY-MM")=A11)*'Customers Raw data'!D2:D1001) -> 15800 | F11: =E11-D11 -> 14850 | G11: =IF(B11>0,REPT("█",MIN(B11,20)),"–") -> ████
A12: 2024-09 | B12: =COUNTIF(Calculations!Q2:Q1001,A12) -> 6 | C12: =SUMPRODUCT((TEXT(DATEVALUE('Customers Raw data'!B2:B1001),"YYYY-MM")=A12)*1) -> 48 | D12: =SUMIF(Calculations!Q2:Q1001,A12,Calculations!P2:P1001) -> 1950 | E12: =SUMPRODUCT((TEXT(DATEVALUE('Customers Raw data'!B2:B1001),"YYYY-MM")=A12)*'Customers Raw data'!D2:D1001) -> 11100 | F12: =E12-D12 -> 9150 | G12: =IF(B12>0,REPT("█",MIN(B12,20)),"–") -> ██████
A13: 2024-10 | B13: =COUNTIF(Calculations!Q2:Q1001,A13) -> 6 | C13: =SUMPRODUCT((TEXT(DATEVALUE('Customers Raw data'!B2:B1001),"YYYY-MM")=A13)*1) -> 59 | D13: =SUMIF(Calculations!Q2:Q1001,A13,Calculations!P2:P1001) -> 1950 | E13: =SUMPRODUCT((TEXT(DATEVALUE('Customers Raw data'!B2:B1001),"YYYY-MM")=A13)*'Customers Raw data'!D2:D1001) -> 12700 | F13: =E13-D13 -> 10750 | G13: =IF(B13>0,REPT("█",MIN(B13,20)),"–") -> ██████
A14: 2024-11 | B14: =COUNTIF(Calculations!Q2:Q1001,A14) -> 8 | C14: =SUMPRODUCT((TEXT(DATEVALUE('Customers Raw data'!B2:B1001),"YYYY-MM")=A14)*1) -> 67 | D14: =SUMIF(Calculations!Q2:Q1001,A14,Calculations!P2:P1001) -> 2200 | E14: =SUMPRODUCT((TEXT(DATEVALUE('Customers Raw data'!B2:B1001),"YYYY-MM")=A14)*'Customers Raw data'!D2:D1001) -> 15650 | F14: =E14-D14 -> 13450 | G14: =IF(B14>0,REPT("█",MIN(B14,20)),"–") -> ████████
A15: 2024-12 | B15: =COUNTIF(Calculations!Q2:Q1001,A15) -> 6 | C15: =SUMPRODUCT((TEXT(DATEVALUE('Customers Raw data'!B2:B1001),"YYYY-MM")=A15)*1) -> 58 | D15: =SUMIF(Calculations!Q2:Q1001,A15,Calculations!P2:P1001) -> 900 | E15: =SUMPRODUCT((TEXT(DATEVALUE('Customers Raw data'!B2:B1001),"YYYY-MM")=A15)*'Customers Raw data'!D2:D1001) -> 17150 | F15: =E15-D15 -> 16250 | G15: =IF(B15>0,REPT("█",MIN(B15,20)),"–") -> ██████
A16: 2025-01 | B16: =COUNTIF(Calculations!Q2:Q1001,A16) -> 6 | C16: =SUMPRODUCT((TEXT(DATEVALUE('Customers Raw data'!B2:B1001),"YYYY-MM")=A16)*1) -> 53 | D16: =SUMIF(Calculations!Q2:Q1001,A16,Calculations!P2:P1001) -> 2100 | E16: =SUMPRODUCT((TEXT(DATEVALUE('Customers Raw data'!B2:B1001),"YYYY-MM")=A16)*'Customers Raw data'!D2:D1001) -> 13600 | F16: =E16-D16 -> 11500 | G16: =IF(B16>0,REPT("█",MIN(B16,20)),"–") -> ██████
A17: 2025-02 | B17: =COUNTIF(Calculations!Q2:Q1001,A17) -> 6 | C17: =SUMPRODUCT((TEXT(DATEVALUE('Customers Raw data'!B2:B1001),"YYYY-MM")=A17)*1) -> 56 | D17: =SUMIF(Calculations!Q2:Q1001,A17,Calculations!P2:P1001) -> 1800 | E17: =SUMPRODUCT((TEXT(DATEVALUE('Customers Raw data'!B2:B1001),"YYYY-MM")=A17)*'Customers Raw data'!D2:D1001) -> 14350 | F17: =E17-D17 -> 12550 | G17: =IF(B17>0,REPT("█",MIN(B17,20)),"–") -> ██████
A18: 2025-03 | B18: =COUNTIF(Calculations!Q2:Q1001,A18) -> 26 | C18: =SUMPRODUCT((TEXT(DATEVALUE('Customers Raw data'!B2:B1001),"YYYY-MM")=A18)*1) -> 65 | D18: =SUMIF(Calculations!Q2:Q1001,A18,Calculations!P2:P1001) -> 7750 | E18: =SUMPRODUCT((TEXT(DATEVALUE('Customers Raw data'!B2:B1001),"YYYY-MM")=A18)*'Customers Raw data'!D2:D1001) -> 13300 | F18: =E18-D18 -> 5550 | G18: =IF(B18>0,REPT("█",MIN(B18,20)),"–") -> ████████████████████
A19: 2025-04 | B19: =COUNTIF(Calculations!Q2:Q1001,A19) -> 23 | C19: =SUMPRODUCT((TEXT(DATEVALUE('Customers Raw data'!B2:B1001),"YYYY-MM")=A19)*1) -> 57 | D19: =SUMIF(Calculations!Q2:Q1001,A19,Calculations!P2:P1001) -> 4000 | E19: =SUMPRODUCT((TEXT(DATEVALUE('Customers Raw data'!B2:B1001),"YYYY-MM")=A19)*'Customers Raw data'!D2:D1001) -> 13800 | F19: =E19-D19 -> 9800 | G19: =IF(B19>0,REPT("█",MIN(B19,20)),"–") -> ████████████████████
A20: 2025-05 | B20: =COUNTIF(Calculations!Q2:Q1001,A20) -> 23 | C20: =SUMPRODUCT((TEXT(DATEVALUE('Customers Raw data'!B2:B1001),"YYYY-MM")=A20)*1) -> 60 | D20: =SUMIF(Calculations!Q2:Q1001,A20,Calculations!P2:P1001) -> 6250 | E20: =SUMPRODUCT((TEXT(DATEVALUE('Customers Raw data'!B2:B1001),"YYYY-MM")=A20)*'Customers Raw data'!D2:D1001) -> 17700 | F20: =E20-D20 -> 11450 | G20: =IF(B20>0,REPT("█",MIN(B20,20)),"–") -> ████████████████████
A21: 2025-06 | B21: =COUNTIF(Calculations!Q2:Q1001,A21) -> 41 | C21: =SUMPRODUCT((TEXT(DATEVALUE('Customers Raw data'!B2:B1001),"YYYY-MM")=A21)*1) -> 50 | D21: =SUMIF(Calculations!Q2:Q1001,A21,Calculations!P2:P1001) -> 9400 | E21: =SUMPRODUCT((TEXT(DATEVALUE('Customers Raw data'!B2:B1001),"YYYY-MM")=A21)*'Customers Raw data'!D2:D1001) -> 13000 | F21: =E21-D21 -> 3600 | G21: =IF(B21>0,REPT("█",MIN(B21,20)),"–") -> ████████████████████

Sheet Correlation_Analysis
A1: CORRELATION ANALYSIS – Churn Drivers
A3: Factor | B3: Column Ref | C3: Corr with Is_Churned | D3: Interpretation | E3: Strength
A4: Monthly Fee | B4: Calculations!D2:Calculations!D1001 | C4: =CORREL(Calculations!D2:D1001,Calculations!G2:G1001) -> 0.00012085383 | D4: Higher fee = less/more churn? | E4: =IF(ABS(C4)>0.5,"Strong",IF(ABS(C4)>0.3,"Moderate","Weak")) -> Weak
A5: Tenure Months | B5: Calculations!L2:Calculations!L1001 | C5: =CORREL(Calculations!L2:L1001,Calculations!G2:G1001) -> -0.68160986 | D5: Longer tenure = lower churn risk | E5: =IF(ABS(C5)>0.5,"Strong",IF(ABS(C5)>0.3,"Moderate","Weak")) -> Strong
A6: Lifetime Value | B6: Calculations!M2:Calculations!M1001 | C6: =CORREL(Calculations!M2:M1001,Calculations!G2:G1001) -> -0.32884608 | D6: Higher LTV = lower churn tendency | E6: =IF(ABS(C6)>0.5,"Strong",IF(ABS(C6)>0.3,"Moderate","Weak")) -> Moderate
A7: Plan Numeric | B7: Calculations!N2:Calculations!N1001 | C7: =CORREL(Calculations!N2:N1001,Calculations!G2:G1001) -> -0.0049630862 | D7: Plan tier vs churn propensity | E7: =IF(ABS(C7)>0.5,"Strong",IF(ABS(C7)>0.3,"Moderate","Weak")) -> Weak
A8: Acq Cost | B8: Calculations!E2:Calculations!E1001 | C8: =CORREL(Calculations!E2:E1001,Calculations!G2:G1001) -> -0.0022577012 | D8: Higher CAC customers churn differently | E8: =IF(ABS(C8)>0.5,"Strong",IF(ABS(C8)>0.3,"Moderate","Weak")) -> Weak

Sheet WhatIf_Scenarios
A1: WHAT-IF SCENARIO: Retention ROI Analysis
A3: ── ASSUMPTIONS (change these blue cells) ──
A5: Retention Improvement % | B5: 0.1
A6: Cost per Retention Intervention | B6: 50
A7: Average MRR per Customer | B7: =AVERAGE(Calculations!D2:D1001) -> 249.95
A8: Total Churned Customers | B8: =SUM(Calculations!G2:G1001) -> 168
A9: Total MRR Lost (Baseline) | B9: =SUM(Calculations!P2:P1001) -> 42000
A11: ── SCENARIO OUTPUTS ──
A12: Customers Saved (Estimated) | B12: =ROUND(B8*B5,0) -> 17
A13: MRR Recovered | B13: =B12*B7 -> 4249.15
A14: Annual Revenue Recovery | B14: =B13*12 -> 50989.8
A15: Intervention Cost (Total) | B15: =B12*B6 -> 850
A16: Net ROI ($) | B16: =B14-B15 -> 50139.8
A17: ROI % | B17: =IFERROR((B14-B15)/B15,0) -> 58.988
A18: Payback Period (months) | B18: =IFERROR(B15/B13,0) -> 0.20004001
A21: ── MULTI-SCENARIO COMPARISON (10% / 20% / 30% Retention Lift) ──
A22: Scenario | B22: Retention % | C22: Customers Saved | D22: MRR Recovered | E22: Annual Revenue | F22: Net ROI
A23: Conservative | B23: 0.1 | C23: =ROUND(B8*B23,0) -> 17 | D23: =C23*B7 -> 4249.15 | E23: =D23*12 -> 50989.8 | F23: =E23-C23*B6 -> 50139.8
A24: Base Case | B24: 0.2 | C24: =ROUND(B8*B24,0) -> 34 | D24: =C24*B7 -> 8498.3 | E24: =D24*12 -> 101979.6 | F24: =E24-C24*B6 -> 100279.6
A25: Optimistic | B25: 0.3 | C25: =ROUND(B8*B25,0) -> 50 | D25: =C25*B7 -> 12497.5 | E25: =D25*12 -> 149970 | F25: =E25-C25*B6 -> 147470
